2024-04-24 12:36:00 ERROR Traceback (most recent call last):
  File "/linkhome/rech/genloc01/udu91zn/.conda/envs/MLenv/lib/python3.11/site-packages/wandb/cli/cli.py", line 105, in wrapper
    return func(*args, **kwargs)
           ^^^^^^^^^^^^^^^^^^^^^
  File "/linkhome/rech/genloc01/udu91zn/.conda/envs/MLenv/lib/python3.11/site-packages/wandb/cli/cli.py", line 249, in login
    wandb.login(
  File "/linkhome/rech/genloc01/udu91zn/.conda/envs/MLenv/lib/python3.11/site-packages/wandb/sdk/wandb_login.py", line 84, in login
    configured = _login(
                 ^^^^^^^
  File "/linkhome/rech/genloc01/udu91zn/.conda/envs/MLenv/lib/python3.11/site-packages/wandb/sdk/wandb_login.py", line 334, in _login
    wlogin.prompt_api_key()
  File "/linkhome/rech/genloc01/udu91zn/.conda/envs/MLenv/lib/python3.11/site-packages/wandb/sdk/wandb_login.py", line 263, in prompt_api_key
    raise UsageError("api_key not configured (no-tty). call " + directive)
wandb.errors.UsageError: api_key not configured (no-tty). call wandb login [your_api_key]

